Workbook
Name StatusList: Lists!$A$2:$A$8
Name PriorityList: Lists!$C$2:$C$4
Name EnergyList: Lists!$E$2:$E$6
Name TimeList: Lists!$G$2:$G$6
Name PriorityWeights: Lists!$L$2:$M$4
Name TimeMinutes: Lists!$N$2:$O$6
Name FocusThemes: Lists!$P$2:$Q$6
Name FilterOptions: 'Task Finder'!$T$1:$T$10

Sheet Lists
A1: Status | C1: Priority | E1: Energy | G1: Estimated Time | I1: Energy Guidelines | L1: Priority | M1: Weight | N1: Time Label | O1: Minutes | P1: Energy | Q1: Suggested Focus
A2: Captured | C2: High | E2: Deep Thinking | G2: 5 mins | I2: Deep Thinking | J2: Complex problems, strategic work, decision-making | L2: High | M2: 30 | N2: 5 mins | O2: 5 | P2: Deep Thinking | Q2: Framework Design & Strategic Work
A3: Next | C3: Medium | E3: Processing | G3: 15 mins | I3: Processing | J3: Routine analysis, execution, review | L3: Medium | M3: 20 | N3: 15 mins | O3: 15 | P3: Processing | Q3: Documentation & Review
A4: In Progress | C4: Low | E4: Admin | G4: 30 mins | I4: Admin | J4: Emails, scheduling, admin tasks | L4: Low | M4: 10 | N4: 30 mins | O4: 30 | P4: Admin | Q4: Administration & Housekeeping
A5: Waiting | E5: Meeting | G5: 60 mins | I5: Meeting | J5: Meetings, calls, collaboration | N5: 60 mins | O5: 60 | P5: Meeting | Q5: Stakeholder Review & Collaboration
A6: Blocked | E6: Low Energy | G6: 90+ mins | N6: 90+ mins | O6: 90 | P6: Low Energy | Q6: Knowledge Capture & Light Tasks
A7: Done
A8: Archive
A20: ← Home

Sheet Home
Y1: system — do not edit | Z1: =IF(MAX('Work Register'!$N$5:$N$500)<=-9000,0,MATCH(MAX('Work Register'!$N$5:$N$500),'Work Register'!$N$5:$N$500,0)+4)
B2: Work Operating System | Z2: =IF(Missions!$O$2,"; "&Missions!$N$2,"")&IF(Missions!$O$3,"; "&Missions!$N$3,"")&IF(Missions!$O$4,"; "&Missions!$N$4,"")&IF(Missions!$O$5,"; "&Missions!$N$5,"")&IF(Missions!$O$6,"; "&Missions!$N$6,"")&IF(Missions!$O$7,"; "&Missions!$N$7,"")&IF(Missions!$O$8,"; "&Missions!$N$8,"")&IF(Missions!$O$9,"; "&Missions!$N$9,"")
B4: New Mission | C4: Today | D4: Work Register | E4: Weekly Review
B6: Work Selection
B7: Available Time | C7: 30 mins | D7: Current Energy | E7: Processing
B9: Recommended Next Task
B10: Mission | C10: =IF($Z$1=0,"No actionable tasks",INDEX('Work Register'!A:A,$Z$1))
B11: Component | C11: =IF($Z$1=0,"—",INDEX('Work Register'!C:C,$Z$1))
B12: Task | C12: =IF($Z$1=0,"—",INDEX('Work Register'!D:D,$Z$1))
B13: Reason | C13: =IF($Z$1=0,"Nothing actionable — review Blocked and Waiting items.",INDEX('Work Register'!O:O,$Z$1))
B14: Estimated Duration | C14: =IF($Z$1=0,"—",INDEX('Work Register'!H:H,$Z$1))
B15: Deliverable | C15: =IF($Z$1=0,"—",INDEX('Work Register'!B:B,$Z$1))
B16: Energy Required | C16: =IF($Z$1=0,"—",INDEX('Work Register'!G:G,$Z$1))
B17: Due Date | C17: =IF($Z$1=0,"—",IFERROR(TEXT(INDEX('Work Register'!I:I,$Z$1),"ddd d mmm"),"No due date"))
B18: Status | C18: =IF($Z$1=0,"—",INDEX('Work Register'!E:E,$Z$1))
B20: Active Missions | C20: Due Today | D20: Blocked | E20: Waiting | F20: Completed This Week
B21: =COUNTIFS('Work Register'!$E:$E,"<>Done",'Work Register'!$E:$E,"<>Archive",'Work Register'!$E:$E,"<>Blocked") | C21: =COUNTIFS('Work Register'!$I:$I,">="&TODAY(),'Work Register'!$I:$I,"<"&TODAY()+1,'Work Register'!$E:$E,"<>Done") | D21: =COUNTIF('Work Register'!$E:$E,"Blocked") | E21: =COUNTIF('Work Register'!$E:$E,"Waiting") | F21: =COUNTIFS('Work Register'!$E:$E,"Done",'Work Register'!$L:$L,">="&(TODAY()-WEEKDAY(TODAY(),3)))
B22: #'Weekly Review'!A1
B23: Workload Balance
B24: Energy | C24: Tasks | D24: Hours | E24: % of Active
B25: Deep Thinking | C25: =SUMPRODUCT(('Work Register'!$G$5:$G$500="Deep Thinking")*(('Work Register'!$E$5:$E$500="Captured")+('Work Register'!$E$5:$E$500="Next")+('Work Register'!$E$5:$E$500="In Progress")+('Work Register'!$E$5:$E$500="Waiting"))) | D25: =ROUND(SUMPRODUCT(('Work Register'!$G$5:$G$500="Deep Thinking")*(('Work Register'!$E$5:$E$500="Captured")+('Work Register'!$E$5:$E$500="Next")+('Work Register'!$E$5:$E$500="In Progress")+('Work Register'!$E$5:$E$500="Waiting"))*'Work Register'!$M$5:$M$500)/60,1) | E25: =IFERROR($D25/$D$30,0)
B26: Processing | C26: =SUMPRODUCT(('Work Register'!$G$5:$G$500="Processing")*(('Work Register'!$E$5:$E$500="Captured")+('Work Register'!$E$5:$E$500="Next")+('Work Register'!$E$5:$E$500="In Progress")+('Work Register'!$E$5:$E$500="Waiting"))) | D26: =ROUND(SUMPRODUCT(('Work Register'!$G$5:$G$500="Processing")*(('Work Register'!$E$5:$E$500="Captured")+('Work Register'!$E$5:$E$500="Next")+('Work Register'!$E$5:$E$500="In Progress")+('Work Register'!$E$5:$E$500="Waiting"))*'Work Register'!$M$5:$M$500)/60,1) | E26: =IFERROR($D26/$D$30,0)
B27: Admin | C27: =SUMPRODUCT(('Work Register'!$G$5:$G$500="Admin")*(('Work Register'!$E$5:$E$500="Captured")+('Work Register'!$E$5:$E$500="Next")+('Work Register'!$E$5:$E$500="In Progress")+('Work Register'!$E$5:$E$500="Waiting"))) | D27: =ROUND(SUMPRODUCT(('Work Register'!$G$5:$G$500="Admin")*(('Work Register'!$E$5:$E$500="Captured")+('Work Register'!$E$5:$E$500="Next")+('Work Register'!$E$5:$E$500="In Progress")+('Work Register'!$E$5:$E$500="Waiting"))*'Work Register'!$M$5:$M$500)/60,1) | E27: =IFERROR($D27/$D$30,0)
B28: Meeting | C28: =SUMPRODUCT(('Work Register'!$G$5:$G$500="Meeting")*(('Work Register'!$E$5:$E$500="Captured")+('Work Register'!$E$5:$E$500="Next")+('Work Register'!$E$5:$E$500="In Progress")+('Work Register'!$E$5:$E$500="Waiting"))) | D28: =ROUND(SUMPRODUCT(('Work Register'!$G$5:$G$500="Meeting")*(('Work Register'!$E$5:$E$500="Captured")+('Work Register'!$E$5:$E$500="Next")+('Work Register'!$E$5:$E$500="In Progress")+('Work Register'!$E$5:$E$500="Waiting"))*'Work Register'!$M$5:$M$500)/60,1) | E28: =IFERROR($D28/$D$30,0)
B29: Low Energy | C29: =SUMPRODUCT(('Work Register'!$G$5:$G$500="Low Energy")*(('Work Register'!$E$5:$E$500="Captured")+('Work Register'!$E$5:$E$500="Next")+('Work Register'!$E$5:$E$500="In Progress")+('Work Register'!$E$5:$E$500="Waiting"))) | D29: =ROUND(SUMPRODUCT(('Work Register'!$G$5:$G$500="Low Energy")*(('Work Register'!$E$5:$E$500="Captured")+('Work Register'!$E$5:$E$500="Next")+('Work Register'!$E$5:$E$500="In Progress")+('Work Register'!$E$5:$E$500="Waiting"))*'Work Register'!$M$5:$M$500)/60,1) | E29: =IFERROR($D29/$D$30,0)
B30: Total | C30: =SUM(C25:C29) | D30: =SUM(D25:D29) | E30: =IFERROR(SUM(E25:E29),0)
B32: Today is Best Suited To
B33: =IFERROR(VLOOKUP(INDEX($B$25:$B$29,MATCH(MAX($D$25:$D$29),$D$25:$D$29,0)),Lists!$P$2:$Q$6,2,FALSE),"Add tasks to Work Register to see a recommendation")
B35: Needs Attention
B36: =COUNTIF(Missions!$O$2:$O$9,TRUE)&" active warning(s)" | F36: #Archive!A1
B37: =IFERROR(IF($Z$2="","",IF(LEFT($Z$2,2)="; ",MID($Z$2,3,9999),$Z$2)),"")
B39: Quick Access
B40: Current Focus | C40: Weekly Review | D40: Task Finder | E40: Missions | F40: Archive

Sheet New Mission
N1: =IF(IF($C$5="","Mission Name","")<>"",", "&IF($C$5="","Mission Name",""),"")&IF(IF($C$6="","Outcome","")<>"",", "&IF($C$6="","Outcome",""),"")&IF(IF($C$8="","Priority","")<>"",", "&IF($C$8="","Priority",""),"")&IF(IF(COUNTIFS($C$17:$C$31,"<>",$D$17:$D$31,"<>",$E$17:$E$31,"<>")=0,"at least one complete Deliverable (Name + Component + Task)","")<>"",", "&IF(COUNTIFS($C$17:$C$31,"<>",$D$17:$D$31,"<>",$E$17:$E$31,"<>")=0,"at least one complete Deliverable (Name + Component + Task)",""),"")
B2: New Mission | N2: =IF(IF(AND(OR($C17<>"",$D17<>"",$E17<>""),NOT(AND($C17<>"",$D17<>"",$E17<>""))),"D1","")<>"",", "&IF(AND(OR($C17<>"",$D17<>"",$E17<>""),NOT(AND($C17<>"",$D17<>"",$E17<>""))),"D1",""),"")&IF(IF(AND(OR($C18<>"",$D18<>"",$E18<>""),NOT(AND($C18<>"",$D18<>"",$E18<>""))),"D2","")<>"",", "&IF(AND(OR($C18<>"",$D18<>"",$E18<>""),NOT(AND($C18<>"",$D18<>"",$E18<>""))),"D2",""),"")&IF(IF(AND(OR($C19<>"",$D19<>"",$E19<>""),NOT(AND($C19<>"",$D19<>"",$E19<>""))),"D3","")<>"",", "&IF(AND(OR($C19<>"",$D19<>"",$E19<>""),NOT(AND($C19<>"",$D19<>"",$E19<>""))),"D3",""),"")&IF(IF(AND(OR($C20<>"",$D20<>"",$E20<>""),NOT(AND($C20<>"",$D20<>"",$E20<>""))),"D4","")<>"",", "&IF(AND(OR($C20<>"",$D20<>"",$E20<>""),NOT(AND($C20<>"",$D20<>"",$E20<>""))),"D4",""),"")&IF(IF(AND(OR($C21<>"",$D21<>"",$E21<>""),NOT(AND($C21<>"",$D21<>"",$E21<>""))),"D5","")<>"",", "&IF(AND(OR($C21<>"",$D21<>"",$E21<>""),NOT(AND($C21<>"",$D21<>"",$E21<>""))),"D5",""),"")&IF(IF(AND(OR($C22<>"",$D22<>"",$E22<>""),NOT(AND($C22<>"",$D22<>"",$E22<>""))),"D6","")<>"",", "&IF(AND(OR($C22<>"",$D22<>"",$E22<>""),NOT(AND($C22<>"",$D22<>"",$E22<>""))),"D6",""),"")&IF(IF(AND(OR($C23<>"",$D23<>"",$E23<>""),NOT(AND($C23<>"",$D23<>"",$E23<>""))),"D7","")<>"",", "&IF(AND(OR($C23<>"",$D23<>"",$E23<>""),NOT(AND($C23<>"",$D23<>"",$E23<>""))),"D7",""),"")&IF(IF(AND(OR($C24<>"",$D24<>"",$E24<>""),NOT(AND($C24<>"",$D24<>"",$E24<>""))),"D8","")<>"",", "&IF(AND(OR($C24<>"",$D24<>"",$E24<>""),NOT(AND($C24<>"",$D24<>"",$E24<>""))),"D8",""),"")&IF(IF(AND(OR($C25<>"",$D25<>"",$E25<>""),NOT(AND($C25<>"",$D25<>"",$E25<>""))),"D9","")<>"",", "&IF(AND(OR($C25<>"",$D25<>"",$E25<>""),NOT(AND($C25<>"",$D25<>"",$E25<>""))),"D9",""),"")&IF(IF(AND(OR($C26<>"",$D26<>"",$E26<>""),NOT(AND($C26<>"",$D26<>"",$E26<>""))),"D10","")<>"",", "&IF(AND(OR($C26<>"",$D26<>"",$E26<>""),NOT(AND($C26<>"",$D26<>"",$E26<>""))),"D10",""),"")&IF(IF(AND(OR($C27<>"",$D27<>"",$E27<>""),NOT(AND($C27<>"",$D27<>"",$E27<>""))),"D11","")<>"",", "&IF(AND(OR($C27<>"",$D27<>"",$E27<>""),NOT(AND($C27<>"",$D27<>"",$E27<>""))),"D11",""),"")&IF(IF(AND(OR($C28<>"",$D28<>"",$E28<>""),NOT(AND($C28<>"",$D28<>"",$E28<>""))),"D12","")<>"",", "&IF(AND(OR($C28<>"",$D28<>"",$E28<>""),NOT(AND($C28<>"",$D28<>"",$E28<>""))),"D12",""),"")&IF(IF(AND(OR($C29<>"",$D29<>"",$E29<>""),NOT(AND($C29<>"",$D29<>"",$E29<>""))),"D13","")<>"",", "&IF(AND(OR($C29<>"",$D29<>"",$E29<>""),NOT(AND($C29<>"",$D29<>"",$E29<>""))),"D13",""),"")&IF(IF(AND(OR($C30<>"",$D30<>"",$E30<>""),NOT(AND($C30<>"",$D30<>"",$E30<>""))),"D14","")<>"",", "&IF(AND(OR($C30<>"",$D30<>"",$E30<>""),NOT(AND($C30<>"",$D30<>"",$E30<>""))),"D14",""),"")&IF(IF(AND(OR($C31<>"",$D31<>"",$E31<>""),NOT(AND($C31<>"",$D31<>"",$E31<>""))),"D15","")<>"",", "&IF(AND(OR($C31<>"",$D31<>"",$E31<>""),NOT(AND($C31<>"",$D31<>"",$E31<>""))),"D15",""),"")
B3: ← Home
B5: Mission Name
B6: Outcome
B7: Why does this exist?
B8: Priority
B9: Due Date
B10: Status
B12: Readiness Check
B13: =IF(AND($C$5<>"",$C$6<>"",$C$8<>"",COUNTIFS($C$17:$C$31,"<>",$D$17:$D$31,"<>",$E$17:$E$31,"<>")>0),"✓ Ready — select and copy the block below into Work Register","⚠ Missing: "&IF($N$1="","",IF(LEFT($N$1,2)=", ",MID($N$1,3,9999),$N$1)))
B14: =IFERROR(IF($N$2<>"","⚠ Incomplete: "&IF($N$2="","",IF(LEFT($N$2,2)=", ",MID($N$2,3,9999),$N$2))&" — missing Deliverable Name, Component, or Task on that row",""),"")
B15: Deliverables
C16: Deliverable Name | D16: Component | E16: Task (First Next Action) | F16: Energy | G16: Estimated Time
B17: D1
B18: D2
B19: D3
B20: D4
B21: D5
B22: D6
B23: D7
B24: D8
B25: D9
B26: D10
B27: D11
B28: D12
... B34: Select A36:K50, copy, then paste into the first empty row of Work Register (starting at column A). Rows for Deliverables you didn't fill in will paste blank — delete them after pasting. Fill in Owner and Notes (columns J and K) either before or after pasting.
A35: Mission | B35: Deliverable | C35: Component | D35: Task | E35: Status | F35: Priority | G35: Energy | H35: Estimated Time | I35: Due Date | J35: Owner | K35: Notes
A36: =IF($C$17="","",$C$5) | B36: =IF($C$17="","",$C$17) | C36: =IF($D$17="","",$D$17) | D36: =IF($E$17="","",$E$17) | E36: =IF($C$17="","",$C$10) | F36: =IF($C$17="","",$C$8) | G36: =IF($C$17="","",$F$17) | H36: =IF($C$17="","",$G$17) | I36: =IF($C$17="","",$C$9)
A37: =IF($C$18="","",$C$5) | B37: =IF($C$18="","",$C$18) | C37: =IF($D$18="","",$D$18) | D37: =IF($E$18="","",$E$18) | E37: =IF($C$18="","",$C$10) | F37: =IF($C$18="","",$C$8) | G37: =IF($C$18="","",$F$18) | H37: =IF($C$18="","",$G$18) | I37: =IF($C$18="","",$C$9)
A38: =IF($C$19="","",$C$5) | B38: =IF($C$19="","",$C$19) | C38: =IF($D$19="","",$D$19) | D38: =IF($E$19="","",$E$19) | E38: =IF($C$19="","",$C$10) | F38: =IF($C$19="","",$C$8) | G38: =IF($C$19="","",$F$19) | H38: =IF($C$19="","",$G$19) | I38: =IF($C$19="","",$C$9)
A39: =IF($C$20="","",$C$5) | B39: =IF($C$20="","",$C$20) | C39: =IF($D$20="","",$D$20) | D39: =IF($E$20="","",$E$20) | E39: =IF($C$20="","",$C$10) | F39: =IF($C$20="","",$C$8) | G39: =IF($C$20="","",$F$20) | H39: =IF($C$20="","",$G$20) | I39: =IF($C$20="","",$C$9)
A40: =IF($C$21="","",$C$5) | B40: =IF($C$21="","",$C$21) | C40: =IF($D$21="","",$D$21) | D40: =IF($E$21="","",$E$21) | E40: =IF($C$21="","",$C$10) | F40: =IF($C$21="","",$C$8) | G40: =IF($C$21="","",$F$21) | H40: =IF($C$21="","",$G$21) | I40: =IF($C$21="","",$C$9)
A41: =IF($C$22="","",$C$5) | B41: =IF($C$22="","",$C$22) | C41: =IF($D$22="","",$D$22) | D41: =IF($E$22="","",$E$22) | E41: =IF($C$22="","",$C$10) | F41: =IF($C$22="","",$C$8) | G41: =IF($C$22="","",$F$22) | H41: =IF($C$22="","",$G$22) | I41: =IF($C$22="","",$C$9)
A42: =IF($C$23="","",$C$5) | B42: =IF($C$23="","",$C$23) | C42: =IF($D$23="","",$D$23) | D42: =IF($E$23="","",$E$23) | E42: =IF($C$23="","",$C$10) | F42: =IF($C$23="","",$C$8) | G42: =IF($C$23="","",$F$23) | H42: =IF($C$23="","",$G$23) | I42: =IF($C$23="","",$C$9)
A43: =IF($C$24="","",$C$5) | B43: =IF($C$24="","",$C$24) | C43: =IF($D$24="","",$D$24) | D43: =IF($E$24="","",$E$24) | E43: =IF($C$24="","",$C$10) | F43: =IF($C$24="","",$C$8) | G43: =IF($C$24="","",$F$24) | H43: =IF($C$24="","",$G$24) | I43: =IF($C$24="","",$C$9)
A44: =IF($C$25="","",$C$5) | B44: =IF($C$25="","",$C$25) | C44: =IF($D$25="","",$D$25) | D44: =IF($E$25="","",$E$25) | E44: =IF($C$25="","",$C$10) | F44: =IF($C$25="","",$C$8) | G44: =IF($C$25="","",$F$25) | H44: =IF($C$25="","",$G$25) | I44: =IF($C$25="","",$C$9)
A45: =IF($C$26="","",$C$5) | B45: =IF($C$26="","",$C$26) | C45: =IF($D$26="","",$D$26) | D45: =IF($E$26="","",$E$26) | E45: =IF($C$26="","",$C$10) | F45: =IF($C$26="","",$C$8) | G45: =IF($C$26="","",$F$26) | H45: =IF($C$26="","",$G$26) | I45: =IF($C$26="","",$C$9)
A46: =IF($C$27="","",$C$5) | B46: =IF($C$27="","",$C$27) | C46: =IF($D$27="","",$D$27) | D46: =IF($E$27="","",$E$27) | E46: =IF($C$27="","",$C$10) | F46: =IF($C$27="","",$C$8) | G46: =IF($C$27="","",$F$27) | H46: =IF($C$27="","",$G$27) | I46: =IF($C$27="","",$C$9)
A47: =IF($C$28="","",$C$5) | B47: =IF($C$28="","",$C$28) | C47: =IF($D$28="","",$D$28) | D47: =IF($E$28="","",$E$28) | E47: =IF($C$28="","",$C$10) | F47: =IF($C$28="","",$C$8) | G47: =IF($C$28="","",$F$28) | H47: =IF($C$28="","",$G$28) | I47: =IF($C$28="","",$C$9)
...

Sheet Work Register
A1: Work Register
A2: ← Home
H3: =COUNTIF($D$5:$D$500,"<>")&" of 496 task rows used" | L3: Columns L–P power the recommendation engine — formulas cover rows 5–500 (496 tasks). Safe to leave as-is.
A4: Mission | B4: Deliverable | C4: Component | D4: Task | E4: Status | F4: Priority | G4: Energy | H4: Estimated Time | I4: Due Date | J4: Owner | K4: Notes | L4: Last Updated | M4: Minutes | N4: Score | O4: Reason | P4: Filter Match | Q4: Term: Priority | R4: Term: Overdue | S4: Term: Due Soon | T4: Term: Time Fit | U4: Term: Energy Fit | V4: Reason (built)
A5: Operational Resilience Framework | B5: Framework | C5: Role Cards | D5: Rewrite Coordinator Role | E5: In Progress | F5: High | G5: Deep Thinking | H5: 90+ mins | I5: 46243.247 | J5: TJR | K5: Updated role mapping | L5: 46239.247 | M5: =IF($D5="","",IFERROR(VLOOKUP($H5,Lists!$N$2:$O$6,2,FALSE),0)) | N5: =IF($D5="","",IF(OR($E5="Blocked",$E5="Done",$E5="Archive"),-9999,IF(AND($E5="Waiting",SUMPRODUCT((($E$5:$E$500="Next")+($E$5:$E$500="In Progress")+($E$5:$E$500="Captured"))*($D$5:$D$500<>""))>0),-500,VLOOKUP($F5,Lists!$L$2:$M$4,2,FALSE)+IF($E5="In Progress",10,0)+IF(AND($I5<>"",$I5<TODAY()),25,0)+IF(AND($I5<>"",$I5>=TODAY(),$I5<=TODAY()+7),15,0)+IF($H5="",0,IF($M5<=VLOOKUP(Home!$C$7,Lists!$N$2:$O$6,2,FALSE),20,-10))+IF($G5=Home!$E$7,15,IF(Home!$E$7="",0,-5))-ROW()/100000))) | O5: =IF($D5="","",IF($N5<=-500,"Not recommended right now",IF($E5="Waiting","Nothing else actionable right now — Waiting on: "&IF($K5="","this item",$K5),MID($V5,4,9999)))) | P5: =IF($D5="","",IF('Task Finder'!$C$6="High Priority",AND($F5="High",$E5<>"Done",$E5<>"Archive"),IF('Task Finder'!$C$6="Due This Week",AND($I5<>"",$I5>=TODAY(),$I5<=TODAY()+7,$E5<>"Done"),IF('Task Finder'!$C$6="Quick Wins (15 mins or less)",AND($M5<=15,$E5<>"Done",$E5<>"Blocked"),IF('Task Finder'!$C$6="Deep Thinking",AND($G5="Deep Thinking",$E5<>"Done"),IF('Task Finder'!$C$6="Processing",AND($G5="Processing",$E5<>"Done"),IF('Task Finder'!$C$6="Blocked",$E5="Blocked",IF('Task Finder'!$C$6="Waiting",$E5="Waiting",IF('Task Finder'!$C$6="Recently Updated",AND($L5<>"",$L5>=TODAY()-7),IF('Task Finder'!$C$6="Keyword",AND('Task Finder'!$C$7<>"",OR(ISNUMBER(SEARCH('Task Finder'!$C$7,$A5)),ISNUMBER(SEARCH('Task Finder'!$C$7,$B5)),ISNUMBER(SEARCH('Task Finder'!$C$7,$C5)),ISNUMBER(SEARCH('Task Finder'!$C$7,$D5)),ISNUMBER(SEARCH('Task Finder'!$C$7,$K5)))),TRUE)))))))))) | Q5: =IF($F5="High","High Priority","") | R5: =IF(AND($I5<>"",$I5<TODAY()),"Overdue","") | S5: =IF(AND($I5<>"",$I5>=TODAY(),$I5<=TODAY()+7),"Due This Week","") | T5: =IF(AND($H5<>"",$M5<=VLOOKUP(Home!$C$7,Lists!$N$2:$O$6,2,FALSE)),$H5&" Task","") | U5: =IF($G5=Home!$E$7,"Fits Current Energy","") | V5: =IF($Q5<>""," • "&$Q5,"")&IF($R5<>""," • "&$R5,"")&IF($S5<>""," • "&$S5,"")&IF($T5<>""," • "&$T5,"")&IF($U5<>""," • "&$U5,"")&" • No Blockers"
A6: Operational Resilience Framework | B6: Framework | C6: Role Cards | D6: Review Governance Section | E6: Waiting | F6: High | G6: Processing | H6: 60 mins | I6: 46252.247 | J6: TJR | K6: Awaiting feedback | L6: 46234.247 | M6: =IF($D6="","",IFERROR(VLOOKUP($H6,Lists!$N$2:$O$6,2,FALSE),0)) | N6: =IF($D6="","",IF(OR($E6="Blocked",$E6="Done",$E6="Archive"),-9999,IF(AND($E6="Waiting",SUMPRODUCT((($E$5:$E$500="Next")+($E$5:$E$500="In Progress")+($E$5:$E$500="Captured"))*($D$5:$D$500<>""))>0),-500,VLOOKUP($F6,Lists!$L$2:$M$4,2,FALSE)+IF($E6="In Progress",10,0)+IF(AND($I6<>"",$I6<TODAY()),25,0)+IF(AND($I6<>"",$I6>=TODAY(),$I6<=TODAY()+7),15,0)+IF($H6="",0,IF($M6<=VLOOKUP(Home!$C$7,Lists!$N$2:$O$6,2,FALSE),20,-10))+IF($G6=Home!$E$7,15,IF(Home!$E$7="",0,-5))-ROW()/100000))) | O6: =IF($D6="","",IF($N6<=-500,"Not recommended right now",IF($E6="Waiting","Nothing else actionable right now — Waiting on: "&IF($K6="","this item",$K6),MID($V6,4,9999)))) | P6: =IF($D6="","",IF('Task Finder'!$C$6="High Priority",AND($F6="High",$E6<>"Done",$E6<>"Archive"),IF('Task Finder'!$C$6="Due This Week",AND($I6<>"",$I6>=TODAY(),$I6<=TODAY()+7,$E6<>"Done"),IF('Task Finder'!$C$6="Quick Wins (15 mins or less)",AND($M6<=15,$E6<>"Done",$E6<>"Blocked"),IF('Task Finder'!$C$6="Deep Thinking",AND($G6="Deep Thinking",$E6<>"Done"),IF('Task Finder'!$C$6="Processing",AND($G6="Processing",$E6<>"Done"),IF('Task Finder'!$C$6="Blocked",$E6="Blocked",IF('Task Finder'!$C$6="Waiting",$E6="Waiting",IF('Task Finder'!$C$6="Recently Updated",AND($L6<>"",$L6>=TODAY()-7),IF('Task Finder'!$C$6="Keyword",AND('Task Finder'!$C$7<>"",OR(ISNUMBER(SEARCH('Task Finder'!$C$7,$A6)),ISNUMBER(SEARCH('Task Finder'!$C$7,$B6)),ISNUMBER(SEARCH('Task Finder'!$C$7,$C6)),ISNUMBER(SEARCH('Task Finder'!$C$7,$D6)),ISNUMBER(SEARCH('Task Finder'!$C$7,$K6)))),TRUE)))))))))) | Q6: =IF($F6="High","High Priority","") | R6: =IF(AND($I6<>"",$I6<TODAY()),"Overdue","") | S6: =IF(AND($I6<>"",$I6>=TODAY(),$I6<=TODAY()+7),"Due This Week","") | T6: =IF(AND($H6<>"",$M6<=VLOOKUP(Home!$C$7,Lists!$N$2:$O$6,2,FALSE)),$H6&" Task","") | U6: =IF($G6=Home!$E$7,"Fits Current Energy","") | V6: =IF($Q6<>""," • "&$Q6,"")&IF($R6<>""," • "&$R6,"")&IF($S6<>""," • "&$S6,"")&IF($T6<>""," • "&$T6,"")&IF($U6<>""," • "&$U6,"")&" • No Blockers"
A7: Operational Resilience Framework | B7: Exercises | C7: Training | D7: Draft Exercise Plan | E7: Captured | F7: Medium | G7: Admin | H7: 30 mins | I7: 46238.247 | J7: TJR | K7: Initial outline needed | L7: 46224.247 | M7: =IF($D7="","",IFERROR(VLOOKUP($H7,Lists!$N$2:$O$6,2,FALSE),0)) | N7: =IF($D7="","",IF(OR($E7="Blocked",$E7="Done",$E7="Archive"),-9999,IF(AND($E7="Waiting",SUMPRODUCT((($E$5:$E$500="Next")+($E$5:$E$500="In Progress")+($E$5:$E$500="Captured"))*($D$5:$D$500<>""))>0),-500,VLOOKUP($F7,Lists!$L$2:$M$4,2,FALSE)+IF($E7="In Progress",10,0)+IF(AND($I7<>"",$I7<TODAY()),25,0)+IF(AND($I7<>"",$I7>=TODAY(),$I7<=TODAY()+7),15,0)+IF($H7="",0,IF($M7<=VLOOKUP(Home!$C$7,Lists!$N$2:$O$6,2,FALSE),20,-10))+IF($G7=Home!$E$7,15,IF(Home!$E$7="",0,-5))-ROW()/100000))) | O7: =IF($D7="","",IF($N7<=-500,"Not recommended right now",IF($E7="Waiting","Nothing else actionable right now — Waiting on: "&IF($K7="","this item",$K7),MID($V7,4,9999)))) | P7: =IF($D7="","",IF('Task Finder'!$C$6="High Priority",AND($F7="High",$E7<>"Done",$E7<>"Archive"),IF('Task Finder'!$C$6="Due This Week",AND($I7<>"",$I7>=TODAY(),$I7<=TODAY()+7,$E7<>"Done"),IF('Task Finder'!$C$6="Quick Wins (15 mins or less)",AND($M7<=15,$E7<>"Done",$E7<>"Blocked"),IF('Task Finder'!$C$6="Deep Thinking",AND($G7="Deep Thinking",$E7<>"Done"),IF('Task Finder'!$C$6="Processing",AND($G7="Processing",$E7<>"Done"),IF('Task Finder'!$C$6="Blocked",$E7="Blocked",IF('Task Finder'!$C$6="Waiting",$E7="Waiting",IF('Task Finder'!$C$6="Recently Updated",AND($L7<>"",$L7>=TODAY()-7),IF('Task Finder'!$C$6="Keyword",AND('Task Finder'!$C$7<>"",OR(ISNUMBER(SEARCH('Task Finder'!$C$7,$A7)),ISNUMBER(SEARCH('Task Finder'!$C$7,$B7)),ISNUMBER(SEARCH('Task Finder'!$C$7,$C7)),ISNUMBER(SEARCH('Task Finder'!$C$7,$D7)),ISNUMBER(SEARCH('Task Finder'!$C$7,$K7)))),TRUE)))))))))) | Q7: =IF($F7="High","High Priority","") | R7: =IF(AND($I7<>"",$I7<TODAY()),"Overdue","") | S7: =IF(AND($I7<>"",$I7>=TODAY(),$I7<=TODAY()+7),"Due This Week","") | T7: =IF(AND($H7<>"",$M7<=VLOOKUP(Home!$C$7,Lists!$N$2:$O$6,2,FALSE)),$H7&" Task","") | U7: =IF($G7=Home!$E$7,"Fits Current Energy","") | V7: =IF($Q7<>""," • "&$Q7,"")&IF($R7<>""," • "&$R7,"")&IF($S7<>""," • "&$S7,"")&IF($T7<>""," • "&$T7,"")&IF($U7<>""," • "&$U7,"")&" • No Blockers"
A8: Operational Resilience Framework | B8: Training | C8: Training | D8: Publish Version 1 | E8: Next | F8: High | G8: Admin | H8: 15 mins | I8: 46241.247 | J8: TJR | K8: Final review pending | L8: 46238.247 | M8: =IF($D8="","",IFERROR(VLOOKUP($H8,Lists!$N$2:$O$6,2,FALSE),0)) | N8: =IF($D8="","",IF(OR($E8="Blocked",$E8="Done",$E8="Archive"),-9999,IF(AND($E8="Waiting",SUMPRODUCT((($E$5:$E$500="Next")+($E$5:$E$500="In Progress")+($E$5:$E$500="Captured"))*($D$5:$D$500<>""))>0),-500,VLOOKUP($F8,Lists!$L$2:$M$4,2,FALSE)+IF($E8="In Progress",10,0)+IF(AND($I8<>"",$I8<TODAY()),25,0)+IF(AND($I8<>"",$I8>=TODAY(),$I8<=TODAY()+7),15,0)+IF($H8="",0,IF($M8<=VLOOKUP(Home!$C$7,Lists!$N$2:$O$6,2,FALSE),20,-10))+IF($G8=Home!$E$7,15,IF(Home!$E$7="",0,-5))-ROW()/100000))) | O8: =IF($D8="","",IF($N8<=-500,"Not recommended right now",IF($E8="Waiting","Nothing else actionable right now — Waiting on: "&IF($K8="","this item",$K8),MID($V8,4,9999)))) | P8: =IF($D8="","",IF('Task Finder'!$C$6="High Priority",AND($F8="High",$E8<>"Done",$E8<>"Archive"),IF('Task Finder'!$C$6="Due This Week",AND($I8<>"",$I8>=TODAY(),$I8<=TODAY()+7,$E8<>"Done"),IF('Task Finder'!$C$6="Quick Wins (15 mins or less)",AND($M8<=15,$E8<>"Done",$E8<>"Blocked"),IF('Task Finder'!$C$6="Deep Thinking",AND($G8="Deep Thinking",$E8<>"Done"),IF('Task Finder'!$C$6="Processing",AND($G8="Processing",$E8<>"Done"),IF('Task Finder'!$C$6="Blocked",$E8="Blocked",IF('Task Finder'!$C$6="Waiting",$E8="Waiting",IF('Task Finder'!$C$6="Recently Updated",AND($L8<>"",$L8>=TODAY()-7),IF('Task Finder'!$C$6="Keyword",AND('Task Finder'!$C$7<>"",OR(ISNUMBER(SEARCH('Task Finder'!$C$7,$A8)),ISNUMBER(SEARCH('Task Finder'!$C$7,$B8)),ISNUMBER(SEARCH('Task Finder'!$C$7,$C8)),ISNUMBER(SEARCH('Task Finder'!$C$7,$D8)),ISNUMBER(SEARCH('Task Finder'!$C$7,$K8)))),TRUE)))))))))) | Q8: =IF($F8="High","High Priority","") | R8: =IF(AND($I8<>"",$I8<TODAY()),"Overdue","") | S8: =IF(AND($I8<>"",$I8>=TODAY(),$I8<=TODAY()+7),"Due This Week","") | T8: =IF(AND($H8<>"",$M8<=VLOOKUP(Home!$C$7,Lists!$N$2:$O$6,2,FALSE)),$H8&" Task","") | U8: =IF($G8=Home!$E$7,"Fits Current Energy","") | V8: =IF($Q8<>""," • "&$Q8,"")&IF($R8<>""," • "&$R8,"")&IF($S8<>""," • "&$S8,"")&IF($T8<>""," • "&$T8,"")&IF($U8<>""," • "&$U8,"")&" • No Blockers"
A9: Operational Resilience Framework | B9: Framework | C9: Role Cards | D9: Send Role Card for Sign-off | E9: Waiting | F9: Medium | G9: Admin | H9: 15 mins | I9: 46245.247 | J9: TJR | K9: Awaiting sponsor sign-off | L9: 46237.247 | M9: =IF($D9="","",IFERROR(VLOOKUP($H9,Lists!$N$2:$O$6,2,FALSE),0)) | N9: =IF($D9="","",IF(OR($E9="Blocked",$E9="Done",$E9="Archive"),-9999,IF(AND($E9="Waiting",SUMPRODUCT((($E$5:$E$500="Next")+($E$5:$E$500="In Progress")+($E$5:$E$500="Captured"))*($D$5:$D$500<>""))>0),-500,VLOOKUP($F9,Lists!$L$2:$M$4,2,FALSE)+IF($E9="In Progress",10,0)+IF(AND($I9<>"",$I9<TODAY()),25,0)+IF(AND($I9<>"",$I9>=TODAY(),$I9<=TODAY()+7),15,0)+IF($H9="",0,IF($M9<=VLOOKUP(Home!$C$7,Lists!$N$2:$O$6,2,FALSE),20,-10))+IF($G9=Home!$E$7,15,IF(Home!$E$7="",0,-5))-ROW()/100000))) | O9: =IF($D9="","",IF($N9<=-500,"Not recommended right now",IF($E9="Waiting","Nothing else actionable right now — Waiting on: "&IF($K9="","this item",$K9),MID($V9,4,9999)))) | P9: =IF($D9="","",IF('Task Finder'!$C$6="High Priority",AND($F9="High",$E9<>"Done",$E9<>"Archive"),IF('Task Finder'!$C$6="Due This Week",AND($I9<>"",$I9>=TODAY(),$I9<=TODAY()+7,$E9<>"Done"),IF('Task Finder'!$C$6="Quick Wins (15 mins or less)",AND($M9<=15,$E9<>"Done",$E9<>"Blocked"),IF('Task Finder'!$C$6="Deep Thinking",AND($G9="Deep Thinking",$E9<>"Done"),IF('Task Finder'!$C$6="Processing",AND($G9="Processing",$E9<>"Done"),IF('Task Finder'!$C$6="Blocked",$E9="Blocked",IF('Task Finder'!$C$6="Waiting",$E9="Waiting",IF('Task Finder'!$C$6="Recently Updated",AND($L9<>"",$L9>=TODAY()-7),IF('Task Finder'!$C$6="Keyword",AND('Task Finder'!$C$7<>"",OR(ISNUMBER(SEARCH('Task Finder'!$C$7,$A9)),ISNUMBER(SEARCH('Task Finder'!$C$7,$B9)),ISNUMBER(SEARCH('Task Finder'!$C$7,$C9)),ISNUMBER(SEARCH('Task Finder'!$C$7,$D9)),ISNUMBER(SEARCH('Task Finder'!$C$7,$K9)))),TRUE)))))))))) | Q9: =IF($F9="High","High Priority","") | R9: =IF(AND($I9<>"",$I9<TODAY()),"Overdue","") | S9: =IF(AND($I9<>"",$I9>=TODAY(),$I9<=TODAY()+7),"Due This Week","") | T9: =IF(AND($H9<>"",$M9<=VLOOKUP(Home!$C$7,Lists!$N$2:$O$6,2,FALSE)),$H9&" Task","") | U9: =IF($G9=Home!$E$7,"Fits Current Energy","") | V9: =IF($Q9<>""," • "&$Q9,"")&IF($R9<>""," • "&$R9,"")&IF($S9<>""," • "&$S9,"")&IF($T9<>""," • "&$T9,"")&IF($U9<>""," • "&$U9,"")&" • No Blockers"
A10: Operational Resilience Framework | B10: Exercises | C10: Training | D10: Confirm Venue Booking | E10: Blocked | F10: Medium | G10: Admin | H10: 15 mins | I10: 46250.247 | J10: TJR | K10: Blocked on facilities team | L10: 46231.247 | M10: =IF($D10="","",IFERROR(VLOOKUP($H10,Lists!$N$2:$O$6,2,FALSE),0)) | N10: =IF($D10="","",IF(OR($E10="Blocked",$E10="Done",$E10="Archive"),-9999,IF(AND($E10="Waiting",SUMPRODUCT((($E$5:$E$500="Next")+($E$5:$E$500="In Progress")+($E$5:$E$500="Captured"))*($D$5:$D$500<>""))>0),-500,VLOOKUP($F10,Lists!$L$2:$M$4,2,FALSE)+IF($E10="In Progress",10,0)+IF(AND($I10<>"",$I10<TODAY()),25,0)+IF(AND($I10<>"",$I10>=TODAY(),$I10<=TODAY()+7),15,0)+IF($H10="",0,IF($M10<=VLOOKUP(Home!$C$7,Lists!$N$2:$O$6,2,FALSE),20,-10))+IF($G10=Home!$E$7,15,IF(Home!$E$7="",0,-5))-ROW()/100000))) | O10: =IF($D10="","",IF($N10<=-500,"Not recommended right now",IF($E10="Waiting","Nothing else actionable right now — Waiting on: "&IF($K10="","this item",$K10),MID($V10,4,9999)))) | P10: =IF($D10="","",IF('Task Finder'!$C$6="High Priority",AND($F10="High",$E10<>"Done",$E10<>"Archive"),IF('Task Finder'!$C$6="Due This Week",AND($I10<>"",$I10>=TODAY(),$I10<=TODAY()+7,$E10<>"Done"),IF('Task Finder'!$C$6="Quick Wins (15 mins or less)",AND($M10<=15,$E10<>"Done",$E10<>"Blocked"),IF('Task Finder'!$C$6="Deep Thinking",AND($G10="Deep Thinking",$E10<>"Done"),IF('Task Finder'!$C$6="Processing",AND($G10="Processing",$E10<>"Done"),IF('Task Finder'!$C$6="Blocked",$E10="Blocked",IF('Task Finder'!$C$6="Waiting",$E10="Waiting",IF('Task Finder'!$C$6="Recently Updated",AND($L10<>"",$L10>=TODAY()-7),IF('Task Finder'!$C$6="Keyword",AND('Task Finder'!$C$7<>"",OR(ISNUMBER(SEARCH('Task Finder'!$C$7,$A10)),ISNUMBER(SEARCH('Task Finder'!$C$7,$B10)),ISNUMBER(SEARCH('Task Finder'!$C$7,$C10)),ISNUMBER(SEARCH('Task Finder'!$C$7,$D10)),ISNUMBER(SEARCH('Task Finder'!$C$7,$K10)))),TRUE)))))))))) | Q10: =IF($F10="High","High Priority","") | R10: =IF(AND($I10<>"",$I10<TODAY()),"Overdue","") | S10: =IF(AND($I10<>"",$I10>=TODAY(),$I10<=TODAY()+7),"Due This Week","") | T10: =IF(AND($H10<>"",$M10<=VLOOKUP(Home!$C$7,Lists!$N$2:$O$6,2,FALSE)),$H10&" Task","") | U10: =IF($G10=Home!$E$7,"Fits Current Energy","") | V10: =IF($Q10<>""," • "&$Q10,"")&IF($R10<>""," • "&$R10,"")&IF($S10<>""," • "&$S10,"")&IF($T10<>""," • "&$T10,"")&IF($U10<>""," • "&$U10,"")&" • No Blockers"
A11: Operational Resilience Framework | B11: Framework | C11: Governance | D11: Tidy Reference List | E11: Next | F11: Low | G11: Admin | H11: 5 mins | J11: TJR | L11: 46239.247 | M11: =IF($D11="","",IFERROR(VLOOKUP($H11,Lists!$N$2:$O$6,2,FALSE),0)) | N11: =IF($D11="","",IF(OR($E11="Blocked",$E11="Done",$E11="Archive"),-9999,IF(AND($E11="Waiting",SUMPRODUCT((($E$5:$E$500="Next")+($E$5:$E$500="In Progress")+($E$5:$E$500="Captured"))*($D$5:$D$500<>""))>0),-500,VLOOKUP($F11,Lists!$L$2:$M$4,2,FALSE)+IF($E11="In Progress",10,0)+IF(AND($I11<>"",$I11<TODAY()),25,0)+IF(AND($I11<>"",$I11>=TODAY(),$I11<=TODAY()+7),15,0)+IF($H11="",0,IF($M11<=VLOOKUP(Home!$C$7,Lists!$N$2:$O$6,2,FALSE),20,-10))+IF($G11=Home!$E$7,15,IF(Home!$E$7="",0,-5))-ROW()/100000))) | O11: =IF($D11="","",IF($N11<=-500,"Not recommended right now",IF($E11="Waiting","Nothing else actionable right now — Waiting on: "&IF($K11="","this item",$K11),MID($V11,4,9999)))) | P11: =IF($D11="","",IF('Task Finder'!$C$6="High Priority",AND($F11="High",$E11<>"Done",$E11<>"Archive"),IF('Task Finder'!$C$6="Due This Week",AND($I11<>"",$I11>=TODAY(),$I11<=TODAY()+7,$E11<>"Done"),IF('Task Finder'!$C$6="Quick Wins (15 mins or less)",AND($M11<=15,$E11<>"Done",$E11<>"Blocked"),IF('Task Finder'!$C$6="Deep Thinking",AND($G11="Deep Thinking",$E11<>"Done"),IF('Task Finder'!$C$6="Processing",AND($G11="Processing",$E11<>"Done"),IF('Task Finder'!$C$6="Blocked",$E11="Blocked",IF('Task Finder'!$C$6="Waiting",$E11="Waiting",IF('Task Finder'!$C$6="Recently Updated",AND($L11<>"",$L11>=TODAY()-7),IF('Task Finder'!$C$6="Keyword",AND('Task Finder'!$C$7<>"",OR(ISNUMBER(SEARCH('Task Finder'!$C$7,$A11)),ISNUMBER(SEARCH('Task Finder'!$C$7,$B11)),ISNUMBER(SEARCH('Task Finder'!$C$7,$C11)),ISNUMBER(SEARCH('Task Finder'!$C$7,$D11)),ISNUMBER(SEARCH('Task Finder'!$C$7,$K11)))),TRUE)))))))))) | Q11: =IF($F11="High","High Priority","") | R11: =IF(AND($I11<>"",$I11<TODAY()),"Overdue","") | S11: =IF(AND($I11<>"",$I11>=TODAY(),$I11<=TODAY()+7),"Due This Week","") | T11: =IF(AND($H11<>"",$M11<=VLOOKUP(Home!$C$7,Lists!$N$2:$O$6,2,FALSE)),$H11&" Task","") | U11: =IF($G11=Home!$E$7,"Fits Current Energy","") | V11: =IF($Q11<>""," • "&$Q11,"")&IF($R11<>""," • "&$R11,"")&IF($S11<>""," • "&$S11,"")&IF($T11<>""," • "&$T11,"")&IF($U11<>""," • "&$U11,"")&" • No Blockers"
A12: Client Onboarding Playbook | B12: Playbook | C12: Welcome Kit | D12: Draft Welcome Email Template | E12: In Progress | F12: High | G12: Processing | H12: 30 mins | I12: 46242.247 | J12: TJR | K12: First draft underway | L12: 46240.247 | M12: =IF($D12="","",IFERROR(VLOOKUP($H12,Lists!$N$2:$O$6,2,FALSE),0)) | N12: =IF($D12="","",IF(OR($E12="Blocked",$E12="Done",$E12="Archive"),-9999,IF(AND($E12="Waiting",SUMPRODUCT((($E$5:$E$500="Next")+($E$5:$E$500="In Progress")+($E$5:$E$500="Captured"))*($D$5:$D$500<>""))>0),-500,VLOOKUP($F12,Lists!$L$2:$M$4,2,FALSE)+IF($E12="In Progress",10,0)+IF(AND($I12<>"",$I12<TODAY()),25,0)+IF(AND($I12<>"",$I12>=TODAY(),$I12<=TODAY()+7),15,0)+IF($H12="",0,IF($M12<=VLOOKUP(Home!$C$7,Lists!$N$2:$O$6,2,FALSE),20,-10))+IF($G12=Home!$E$7,15,IF(Home!$E$7="",0,-5))-ROW()/100000))) | O12: =IF($D12="","",IF($N12<=-500,"Not recommended right now",IF($E12="Waiting","Nothing else actionable right now — Waiting on: "&IF($K12="","this item",$K12),MID($V12,4,9999)))) | P12: =IF($D12="","",IF('Task Finder'!$C$6="High Priority",AND($F12="High",$E12<>"Done",$E12<>"Archive"),IF('Task Finder'!$C$6="Due This Week",AND($I12<>"",$I12>=TODAY(),$I12<=TODAY()+7,$E12<>"Done"),IF('Task Finder'!$C$6="Quick Wins (15 mins or less)",AND($M12<=15,$E12<>"Done",$E12<>"Blocked"),IF('Task Finder'!$C$6="Deep Thinking",AND($G12="Deep Thinking",$E12<>"Done"),IF('Task Finder'!$C$6="Processing",AND($G12="Processing",$E12<>"Done"),IF('Task Finder'!$C$6="Blocked",$E12="Blocked",IF('Task Finder'!$C$6="Waiting",$E12="Waiting",IF('Task Finder'!$C$6="Recently Updated",AND($L12<>"",$L12>=TODAY()-7),IF('Task Finder'!$C$6="Keyword",AND('Task Finder'!$C$7<>"",OR(ISNUMBER(SEARCH('Task Finder'!$C$7,$A12)),ISNUMBER(SEARCH('Task Finder'!$C$7,$B12)),ISNUMBER(SEARCH('Task Finder'!$C$7,$C12)),ISNUMBER(SEARCH('Task Finder'!$C$7,$D12)),ISNUMBER(SEARCH('Task Finder'!$C$7,$K12)))),TRUE)))))))))) | Q12: =IF($F12="High","High Priority","") | R12: =IF(AND($I12<>"",$I12<TODAY()),"Overdue","") | S12: =IF(AND($I12<>"",$I12>=TODAY(),$I12<=TODAY()+7),"Due This Week","") | T12: =IF(AND($H12<>"",$M12<=VLOOKUP(Home!$C$7,Lists!$N$2:$O$6,2,FALSE)),$H12&" Task","") | U12: =IF($G12=Home!$E$7,"Fits Current Energy","") | V12: =IF($Q12<>""," • "&$Q12,"")&IF($R12<>""," • "&$R12,"")&IF($S12<>""," • "&$S12,"")&IF($T12<>""," • "&$T12,"")&IF($U12<>""," • "&$U12,"")&" • No Blockers"
A13: Client Onboarding Playbook | B13: Playbook | C13: Welcome Kit | D13: List Required Access Requests | E13: Next | F13: Medium | G13: Admin | H13: 15 mins | I13: 46246.247 | J13: TJR | L13: 46236.247 | M13: =IF($D13="","",IFERROR(VLOOKUP($H13,Lists!$N$2:$O$6,2,FALSE),0)) | N13: =IF($D13="","",IF(OR($E13="Blocked",$E13="Done",$E13="Archive"),-9999,IF(AND($E13="Waiting",SUMPRODUCT((($E$5:$E$500="Next")+($E$5:$E$500="In Progress")+($E$5:$E$500="Captured"))*($D$5:$D$500<>""))>0),-500,VLOOKUP($F13,Lists!$L$2:$M$4,2,FALSE)+IF($E13="In Progress",10,0)+IF(AND($I13<>"",$I13<TODAY()),25,0)+IF(AND($I13<>"",$I13>=TODAY(),$I13<=TODAY()+7),15,0)+IF($H13="",0,IF($M13<=VLOOKUP(Home!$C$7,Lists!$N$2:$O$6,2,FALSE),20,-10))+IF($G13=Home!$E$7,15,IF(Home!$E$7="",0,-5))-ROW()/100000))) | O13: =IF($D13="","",IF($N13<=-500,"Not recommended right now",IF($E13="Waiting","Nothing else actionable right now — Waiting on: "&IF($K13="","this item",$K13),MID($V13,4,9999)))) | P13: =IF($D13="","",IF('Task Finder'!$C$6="High Priority",AND($F13="High",$E13<>"Done",$E13<>"Archive"),IF('Task Finder'!$C$6="Due This Week",AND($I13<>"",$I13>=TODAY(),$I13<=TODAY()+7,$E13<>"Done"),IF('Task Finder'!$C$6="Quick Wins (15 mins or less)",AND($M13<=15,$E13<>"Done",$E13<>"Blocked"),IF('Task Finder'!$C$6="Deep Thinking",AND($G13="Deep Thinking",$E13<>"Done"),IF('Task Finder'!$C$6="Processing",AND($G13="Processing",$E13<>"Done"),IF('Task Finder'!$C$6="Blocked",$E13="Blocked",IF('Task Finder'!$C$6="Waiting",$E13="Waiting",IF('Task Finder'!$C$6="Recently Updated",AND($L13<>"",$L13>=TODAY()-7),IF('Task Finder'!$C$6="Keyword",AND('Task Finder'!$C$7<>"",OR(ISNUMBER(SEARCH('Task Finder'!$C$7,$A13)),ISNUMBER(SEARCH('Task Finder'!$C$7,$B13)),ISNUMBER(SEARCH('Task Finder'!$C$7,$C13)),ISNUMBER(SEARCH('Task Finder'!$C$7,$D13)),ISNUMBER(SEARCH('Task Finder'!$C$7,$K13)))),TRUE)))))))))) | Q13: =IF($F13="High","High Priority","") | R13: =IF(AND($I13<>"",$I13<TODAY()),"Overdue","") | S13: =IF(AND($I13<>"",$I13>=TODAY(),$I13<=TODAY()+7),"Due This Week","") | T13: =IF(AND($H13<>"",$M13<=VLOOKUP(Home!$C$7,Lists!$N$2:$O$6,2,FALSE)),$H13&" Task","") | U13: =IF($G13=Home!$E$7,"Fits Current Energy","") | V13: =IF($Q13<>""," • "&$Q13,"")&IF($R13<>""," • "&$R13,"")&IF($S13<>""," • "&$S13,"")&IF($T13<>""," • "&$T13,"")&IF($U13<>""," • "&$U13,"")&" • No Blockers"
M14: =IF($D14="","",IFERROR(VLOOKUP($H14,Lists!$N$2:$O$6,2,FALSE),0)) | N14: =IF($D14="","",IF(OR($E14="Blocked",$E14="Done",$E14="Archive"),-9999,IF(AND($E14="Waiting",SUMPRODUCT((($E$5:$E$500="Next")+($E$5:$E$500="In Progress")+($E$5:$E$500="Captured"))*($D$5:$D$500<>""))>0),-500,VLOOKUP($F14,Lists!$L$2:$M$4,2,FALSE)+IF($E14="In Progress",10,0)+IF(AND($I14<>"",$I14<TODAY()),25,0)+IF(AND($I14<>"",$I14>=TODAY(),$I14<=TODAY()+7),15,0)+IF($H14="",0,IF($M14<=VLOOKUP(Home!$C$7,Lists!$N$2:$O$6,2,FALSE),20,-10))+IF($G14=Home!$E$7,15,IF(Home!$E$7="",0,-5))-ROW()/100000))) | O14: =IF($D14="","",IF($N14<=-500,"Not recommended right now",IF($E14="Waiting","Nothing else actionable right now — Waiting on: "&IF($K14="","this item",$K14),MID($V14,4,9999)))) | P14: =IF($D14="","",IF('Task Finder'!$C$6="High Priority",AND($F14="High",$E14<>"Done",$E14<>"Archive"),IF('Task Finder'!$C$6="Due This Week",AND($I14<>"",$I14>=TODAY(),$I14<=TODAY()+7,$E14<>"Done"),IF('Task Finder'!$C$6="Quick Wins (15 mins or less)",AND($M14<=15,$E14<>"Done",$E14<>"Blocked"),IF('Task Finder'!$C$6="Deep Thinking",AND($G14="Deep Thinking",$E14<>"Done"),IF('Task Finder'!$C$6="Processing",AND($G14="Processing",$E14<>"Done"),IF('Task Finder'!$C$6="Blocked",$E14="Blocked",IF('Task Finder'!$C$6="Waiting",$E14="Waiting",IF('Task Finder'!$C$6="Recently Updated",AND($L14<>"",$L14>=TODAY()-7),IF('Task Finder'!$C$6="Keyword",AND('Task Finder'!$C$7<>"",OR(ISNUMBER(SEARCH('Task Finder'!$C$7,$A14)),ISNUMBER(SEARCH('Task Finder'!$C$7,$B14)),ISNUMBER(SEARCH('Task Finder'!$C$7,$C14)),ISNUMBER(SEARCH('Task Finder'!$C$7,$D14)),ISNUMBER(SEARCH('Task Finder'!$C$7,$K14)))),TRUE)))))))))) | Q14: =IF($F14="High","High Priority","") | R14: =IF(AND($I14<>"",$I14<TODAY()),"Overdue","") | S14: =IF(AND($I14<>"",$I14>=TODAY(),$I14<=TODAY()+7),"Due This Week","") | T14: =IF(AND($H14<>"",$M14<=VLOOKUP(Home!$C$7,Lists!$N$2:$O$6,2,FALSE)),$H14&" Task","") | U14: =IF($G14=Home!$E$7,"Fits Current Energy","") | V14: =IF($Q14<>""," • "&$Q14,"")&IF($R14<>""," • "&$R14,"")&IF($S14<>""," • "&$S14,"")&IF($T14<>""," • "&$T14,"")&IF($U14<>""," • "&$U14,"")&" • No Blockers"
M15: =IF($D15="","",IFERROR(VLOOKUP($H15,Lists!$N$2:$O$6,2,FALSE),0)) | N15: =IF($D15="","",IF(OR($E15="Blocked",$E15="Done",$E15="Archive"),-9999,IF(AND($E15="Waiting",SUMPRODUCT((($E$5:$E$500="Next")+($E$5:$E$500="In Progress")+($E$5:$E$500="Captured"))*($D$5:$D$500<>""))>0),-500,VLOOKUP($F15,Lists!$L$2:$M$4,2,FALSE)+IF($E15="In Progress",10,0)+IF(AND($I15<>"",$I15<TODAY()),25,0)+IF(AND($I15<>"",$I15>=TODAY(),$I15<=TODAY()+7),15,0)+IF($H15="",0,IF($M15<=VLOOKUP(Home!$C$7,Lists!$N$2:$O$6,2,FALSE),20,-10))+IF($G15=Home!$E$7,15,IF(Home!$E$7="",0,-5))-ROW()/100000))) | O15: =IF($D15="","",IF($N15<=-500,"Not recommended right now",IF($E15="Waiting","Nothing else actionable right now — Waiting on: "&IF($K15="","this item",$K15),MID($V15,4,9999)))) | P15: =IF($D15="","",IF('Task Finder'!$C$6="High Priority",AND($F15="High",$E15<>"Done",$E15<>"Archive"),IF('Task Finder'!$C$6="Due This Week",AND($I15<>"",$I15>=TODAY(),$I15<=TODAY()+7,$E15<>"Done"),IF('Task Finder'!$C$6="Quick Wins (15 mins or less)",AND($M15<=15,$E15<>"Done",$E15<>"Blocked"),IF('Task Finder'!$C$6="Deep Thinking",AND($G15="Deep Thinking",$E15<>"Done"),IF('Task Finder'!$C$6="Processing",AND($G15="Processing",$E15<>"Done"),IF('Task Finder'!$C$6="Blocked",$E15="Blocked",IF('Task Finder'!$C$6="Waiting",$E15="Waiting",IF('Task Finder'!$C$6="Recently Updated",AND($L15<>"",$L15>=TODAY()-7),IF('Task Finder'!$C$6="Keyword",AND('Task Finder'!$C$7<>"",OR(ISNUMBER(SEARCH('Task Finder'!$C$7,$A15)),ISNUMBER(SEARCH('Task Finder'!$C$7,$B15)),ISNUMBER(SEARCH('Task Finder'!$C$7,$C15)),ISNUMBER(SEARCH('Task Finder'!$C$7,$D15)),ISNUMBER(SEARCH('Task Finder'!$C$7,$K15)))),TRUE)))))))))) | Q15: =IF($F15="High","High Priority","") | R15: =IF(AND($I15<>"",$I15<TODAY()),"Overdue","") | S15: =IF(AND($I15<>"",$I15>=TODAY(),$I15<=TODAY()+7),"Due This Week","") | T15: =IF(AND($H15<>"",$M15<=VLOOKUP(Home!$C$7,Lists!$N$2:$O$6,2,FALSE)),$H15&" Task","") | U15: =IF($G15=Home!$E$7,"Fits Current Energy","") | V15: =IF($Q15<>""," • "&$Q15,"")&IF($R15<>""," • "&$R15,"")&IF($S15<>""," • "&$S15,"")&IF($T15<>""," • "&$T15,"")&IF($U15<>""," • "&$U15,"")&" • No Blockers"
M16: =IF($D16="","",IFERROR(VLOOKUP($H16,Lists!$N$2:$O$6,2,FALSE),0)) | N16: =IF($D16="","",IF(OR($E16="Blocked",$E16="Done",$E16="Archive"),-9999,IF(AND($E16="Waiting",SUMPRODUCT((($E$5:$E$500="Next")+($E$5:$E$500="In Progress")+($E$5:$E$500="Captured"))*($D$5:$D$500<>""))>0),-500,VLOOKUP($F16,Lists!$L$2:$M$4,2,FALSE)+IF($E16="In Progress",10,0)+IF(AND($I16<>"",$I16<TODAY()),25,0)+IF(AND($I16<>"",$I16>=TODAY(),$I16<=TODAY()+7),15,0)+IF($H16="",0,IF($M16<=VLOOKUP(Home!$C$7,Lists!$N$2:$O$6,2,FALSE),20,-10))+IF($G16=Home!$E$7,15,IF(Home!$E$7="",0,-5))-ROW()/100000))) | O16: =IF($D16="","",IF($N16<=-500,"Not recommended right now",IF($E16="Waiting","Nothing else actionable right now — Waiting on: "&IF($K16="","this item",$K16),MID($V16,4,9999)))) | P16: =IF($D16="","",IF('Task Finder'!$C$6="High Priority",AND($F16="High",$E16<>"Done",$E16<>"Archive"),IF('Task Finder'!$C$6="Due This Week",AND($I16<>"",$I16>=TODAY(),$I16<=TODAY()+7,$E16<>"Done"),IF('Task Finder'!$C$6="Quick Wins (15 mins or less)",AND($M16<=15,$E16<>"Done",$E16<>"Blocked"),IF('Task Finder'!$C$6="Deep Thinking",AND($G16="Deep Thinking",$E16<>"Done"),IF('Task Finder'!$C$6="Processing",AND($G16="Processing",$E16<>"Done"),IF('Task Finder'!$C$6="Blocked",$E16="Blocked",IF('Task Finder'!$C$6="Waiting",$E16="Waiting",IF('Task Finder'!$C$6="Recently Updated",AND($L16<>"",$L16>=TODAY()-7),IF('Task Finder'!$C$6="Keyword",AND('Task Finder'!$C$7<>"",OR(ISNUMBER(SEARCH('Task Finder'!$C$7,$A16)),ISNUMBER(SEARCH('Task Finder'!$C$7,$B16)),ISNUMBER(SEARCH('Task Finder'!$C$7,$C16)),ISNUMBER(SEARCH('Task Finder'!$C$7,$D16)),ISNUMBER(SEARCH('Task Finder'!$C$7,$K16)))),TRUE)))))))))) | Q16: =IF($F16="High","High Priority","") | R16: =IF(AND($I16<>"",$I16<TODAY()),"Overdue","") | S16: =IF(AND($I16<>"",$I16>=TODAY(),$I16<=TODAY()+7),"Due This Week","") | T16: =IF(AND($H16<>"",$M16<=VLOOKUP(Home!$C$7,Lists!$N$2:$O$6,2,FALSE)),$H16&" Task","") | U16: =IF($G16=Home!$E$7,"Fits Current Energy","") | V16: =IF($Q16<>""," • "&$Q16,"")&IF($R16<>""," • "&$R16,"")&IF($S16<>""," • "&$S16,"")&IF($T16<>""," • "&$T16,"")&IF($U16<>""," • "&$U16,"")&" • No Blockers"
M17: =IF($D17="","",IFERROR(VLOOKUP($H17,Lists!$N$2:$O$6,2,FALSE),0)) | N17: =IF($D17="","",IF(OR($E17="Blocked",$E17="Done",$E17="Archive"),-9999,IF(AND($E17="Waiting",SUMPRODUCT((($E$5:$E$500="Next")+($E$5:$E$500="In Progress")+($E$5:$E$500="Captured"))*($D$5:$D$500<>""))>0),-500,VLOOKUP($F17,Lists!$L$2:$M$4,2,FALSE)+IF($E17="In Progress",10,0)+IF(AND($I17<>"",$I17<TODAY()),25,0)+IF(AND($I17<>"",$I17>=TODAY(),$I17<=TODAY()+7),15,0)+IF($H17="",0,IF($M17<=VLOOKUP(Home!$C$7,Lists!$N$2:$O$6,2,FALSE),20,-10))+IF($G17=Home!$E$7,15,IF(Home!$E$7="",0,-5))-ROW()/100000))) | O17: =IF($D17="","",IF($N17<=-500,"Not recommended right now",IF($E17="Waiting","Nothing else actionable right now — Waiting on: "&IF($K17="","this item",$K17),MID($V17,4,9999)))) | P17: =IF($D17="","",IF('Task Finder'!$C$6="High Priority",AND($F17="High",$E17<>"Done",$E17<>"Archive"),IF('Task Finder'!$C$6="Due This Week",AND($I17<>"",$I17>=TODAY(),$I17<=TODAY()+7,$E17<>"Done"),IF('Task Finder'!$C$6="Quick Wins (15 mins or less)",AND($M17<=15,$E17<>"Done",$E17<>"Blocked"),IF('Task Finder'!$C$6="Deep Thinking",AND($G17="Deep Thinking",$E17<>"Done"),IF('Task Finder'!$C$6="Processing",AND($G17="Processing",$E17<>"Done"),IF('Task Finder'!$C$6="Blocked",$E17="Blocked",IF('Task Finder'!$C$6="Waiting",$E17="Waiting",IF('Task Finder'!$C$6="Recently Updated",AND($L17<>"",$L17>=TODAY()-7),IF('Task Finder'!$C$6="Keyword",AND('Task Finder'!$C$7<>"",OR(ISNUMBER(SEARCH('Task Finder'!$C$7,$A17)),ISNUMBER(SEARCH('Task Finder'!$C$7,$B17)),ISNUMBER(SEARCH('Task Finder'!$C$7,$C17)),ISNUMBER(SEARCH('Task Finder'!$C$7,$D17)),ISNUMBER(SEARCH('Task Finder'!$C$7,$K17)))),TRUE)))))))))) | Q17: =IF($F17="High","High Priority","") | R17: =IF(AND($I17<>"",$I17<TODAY()),"Overdue","") | S17: =IF(AND($I17<>"",$I17>=TODAY(),$I17<=TODAY()+7),"Due This Week","") | T17: =IF(AND($H17<>"",$M17<=VLOOKUP(Home!$C$7,Lists!$N$2:$O$6,2,FALSE)),$H17&" Task","") | U17: =IF($G17=Home!$E$7,"Fits Current Energy","") | V17: =IF($Q17<>""," • "&$Q17,"")&IF($R17<>""," • "&$R17,"")&IF($S17<>""," • "&$S17,"")&IF($T17<>""," • "&$T17,"")&IF($U17<>""," • "&$U17,"")&" • No Blockers"
M18: =IF($D18="","",IFERROR(VLOOKUP($H18,Lists!$N$2:$O$6,2,FALSE),0)) | N18: =IF($D18="","",IF(OR($E18="Blocked",$E18="Done",$E18="Archive"),-9999,IF(AND($E18="Waiting",SUMPRODUCT((($E$5:$E$500="Next")+($E$5:$E$500="In Progress")+($E$5:$E$500="Captured"))*($D$5:$D$500<>""))>0),-500,VLOOKUP($F18,Lists!$L$2:$M$4,2,FALSE)+IF($E18="In Progress",10,0)+IF(AND($I18<>"",$I18<TODAY()),25,0)+IF(AND($I18<>"",$I18>=TODAY(),$I18<=TODAY()+7),15,0)+IF($H18="",0,IF($M18<=VLOOKUP(Home!$C$7,Lists!$N$2:$O$6,2,FALSE),20,-10))+IF($G18=Home!$E$7,15,IF(Home!$E$7="",0,-5))-ROW()/100000))) | O18: =IF($D18="","",IF($N18<=-500,"Not recommended right now",IF($E18="Waiting","Nothing else actionable right now — Waiting on: "&IF($K18="","this item",$K18),MID($V18,4,9999)))) | P18: =IF($D18="","",IF('Task Finder'!$C$6="High Priority",AND($F18="High",$E18<>"Done",$E18<>"Archive"),IF('Task Finder'!$C$6="Due This Week",AND($I18<>"",$I18>=TODAY(),$I18<=TODAY()+7,$E18<>"Done"),IF('Task Finder'!$C$6="Quick Wins (15 mins or less)",AND($M18<=15,$E18<>"Done",$E18<>"Blocked"),IF('Task Finder'!$C$6="Deep Thinking",AND($G18="Deep Thinking",$E18<>"Done"),IF('Task Finder'!$C$6="Processing",AND($G18="Processing",$E18<>"Done"),IF('Task Finder'!$C$6="Blocked",$E18="Blocked",IF('Task Finder'!$C$6="Waiting",$E18="Waiting",IF('Task Finder'!$C$6="Recently Updated",AND($L18<>"",$L18>=TODAY()-7),IF('Task Finder'!$C$6="Keyword",AND('Task Finder'!$C$7<>"",OR(ISNUMBER(SEARCH('Task Finder'!$C$7,$A18)),ISNUMBER(SEARCH('Task Finder'!$C$7,$B18)),ISNUMBER(SEARCH('Task Finder'!$C$7,$C18)),ISNUMBER(SEARCH('Task Finder'!$C$7,$D18)),ISNUMBER(SEARCH('Task Finder'!$C$7,$K18)))),TRUE)))))))))) | Q18: =IF($F18="High","High Priority","") | R18: =IF(AND($I18<>"",$I18<TODAY()),"Overdue","") | S18: =IF(AND($I18<>"",$I18>=TODAY(),$I18<=TODAY()+7),"Due This Week","") | T18: =IF(AND($H18<>"",$M18<=VLOOKUP(Home!$C$7,Lists!$N$2:$O$6,2,FALSE)),$H18&" Task","") | U18: =IF($G18=Home!$E$7,"Fits Current Energy","") | V18: =IF($Q18<>""," • "&$Q18,"")&IF($R18<>""," • "&$R18,"")&IF($S18<>""," • "&$S18,"")&IF($T18<>""," • "&$T18,"")&IF($U18<>""," • "&$U18,"")&" • No Blockers"
M19: =IF($D19="","",IFERROR(VLOOKUP($H19,Lists!$N$2:$O$6,2,FALSE),0)) | N19: =IF($D19="","",IF(OR($E19="Blocked",$E19="Done",$E19="Archive"),-9999,IF(AND($E19="Waiting",SUMPRODUCT((($E$5:$E$500="Next")+($E$5:$E$500="In Progress")+($E$5:$E$500="Captured"))*($D$5:$D$500<>""))>0),-500,VLOOKUP($F19,Lists!$L$2:$M$4,2,FALSE)+IF($E19="In Progress",10,0)+IF(AND($I19<>"",$I19<TODAY()),25,0)+IF(AND($I19<>"",$I19>=TODAY(),$I19<=TODAY()+7),15,0)+IF($H19="",0,IF($M19<=VLOOKUP(Home!$C$7,Lists!$N$2:$O$6,2,FALSE),20,-10))+IF($G19=Home!$E$7,15,IF(Home!$E$7="",0,-5))-ROW()/100000))) | O19: =IF($D19="","",IF($N19<=-500,"Not recommended right now",IF($E19="Waiting","Nothing else actionable right now — Waiting on: "&IF($K19="","this item",$K19),MID($V19,4,9999)))) | P19: =IF($D19="","",IF('Task Finder'!$C$6="High Priority",AND($F19="High",$E19<>"Done",$E19<>"Archive"),IF('Task Finder'!$C$6="Due This Week",AND($I19<>"",$I19>=TODAY(),$I19<=TODAY()+7,$E19<>"Done"),IF('Task Finder'!$C$6="Quick Wins (15 mins or less)",AND($M19<=15,$E19<>"Done",$E19<>"Blocked"),IF('Task Finder'!$C$6="Deep Thinking",AND($G19="Deep Thinking",$E19<>"Done"),IF('Task Finder'!$C$6="Processing",AND($G19="Processing",$E19<>"Done"),IF('Task Finder'!$C$6="Blocked",$E19="Blocked",IF('Task Finder'!$C$6="Waiting",$E19="Waiting",IF('Task Finder'!$C$6="Recently Updated",AND($L19<>"",$L19>=TODAY()-7),IF('Task Finder'!$C$6="Keyword",AND('Task Finder'!$C$7<>"",OR(ISNUMBER(SEARCH('Task Finder'!$C$7,$A19)),ISNUMBER(SEARCH('Task Finder'!$C$7,$B19)),ISNUMBER(SEARCH('Task Finder'!$C$7,$C19)),ISNUMBER(SEARCH('Task Finder'!$C$7,$D19)),ISNUMBER(SEARCH('Task Finder'!$C$7,$K19)))),TRUE)))))))))) | Q19: =IF($F19="High","High Priority","") | R19: =IF(AND($I19<>"",$I19<TODAY()),"Overdue","") | S19: =IF(AND($I19<>"",$I19>=TODAY(),$I19<=TODAY()+7),"Due This Week","") | T19: =IF(AND($H19<>"",$M19<=VLOOKUP(Home!$C$7,Lists!$N$2:$O$6,2,FALSE)),$H19&" Task","") | U19: =IF($G19=Home!$E$7,"Fits Current Energy","") | V19: =IF($Q19<>""," • "&$Q19,"")&IF($R19<>""," • "&$R19,"")&IF($S19<>""," • "&$S19,"")&IF($T19<>""," • "&$T19,"")&IF($U19<>""," • "&$U19,"")&" • No Blockers"
M20: =IF($D20="","",IFERROR(VLOOKUP($H20,Lists!$N$2:$O$6,2,FALSE),0)) | N20: =IF($D20="","",IF(OR($E20="Blocked",$E20="Done",$E20="Archive"),-9999,IF(AND($E20="Waiting",SUMPRODUCT((($E$5:$E$500="Next")+($E$5:$E$500="In Progress")+($E$5:$E$500="Captured"))*($D$5:$D$500<>""))>0),-500,VLOOKUP($F20,Lists!$L$2:$M$4,2,FALSE)+IF($E20="In Progress",10,0)+IF(AND($I20<>"",$I20<TODAY()),25,0)+IF(AND($I20<>"",$I20>=TODAY(),$I20<=TODAY()+7),15,0)+IF($H20="",0,IF($M20<=VLOOKUP(Home!$C$7,Lists!$N$2:$O$6,2,FALSE),20,-10))+IF($G20=Home!$E$7,15,IF(Home!$E$7="",0,-5))-ROW()/100000))) | O20: =IF($D20="","",IF($N20<=-500,"Not recommended right now",IF($E20="Waiting","Nothing else actionable right now — Waiting on: "&IF($K20="","this item",$K20),MID($V20,4,9999)))) | P20: =IF($D20="","",IF('Task Finder'!$C$6="High Priority",AND($F20="High",$E20<>"Done",$E20<>"Archive"),IF('Task Finder'!$C$6="Due This Week",AND($I20<>"",$I20>=TODAY(),$I20<=TODAY()+7,$E20<>"Done"),IF('Task Finder'!$C$6="Quick Wins (15 mins or less)",AND($M20<=15,$E20<>"Done",$E20<>"Blocked"),IF('Task Finder'!$C$6="Deep Thinking",AND($G20="Deep Thinking",$E20<>"Done"),IF('Task Finder'!$C$6="Processing",AND($G20="Processing",$E20<>"Done"),IF('Task Finder'!$C$6="Blocked",$E20="Blocked",IF('Task Finder'!$C$6="Waiting",$E20="Waiting",IF('Task Finder'!$C$6="Recently Updated",AND($L20<>"",$L20>=TODAY()-7),IF('Task Finder'!$C$6="Keyword",AND('Task Finder'!$C$7<>"",OR(ISNUMBER(SEARCH('Task Finder'!$C$7,$A20)),ISNUMBER(SEARCH('Task Finder'!$C$7,$B20)),ISNUMBER(SEARCH('Task Finder'!$C$7,$C20)),ISNUMBER(SEARCH('Task Finder'!$C$7,$D20)),ISNUMBER(SEARCH('Task Finder'!$C$7,$K20)))),TRUE)))))))))) | Q20: =IF($F20="High","High Priority","") | R20: =IF(AND($I20<>"",$I20<TODAY()),"Overdue","") | S20: =IF(AND($I20<>"",$I20>=TODAY(),$I20<=TODAY()+7),"Due This Week","") | T20: =IF(AND($H20<>"",$M20<=VLOOKUP(Home!$C$7,Lists!$N$2:$O$6,2,FALSE)),$H20&" Task","") | U20: =IF($G20=Home!$E$7,"Fits Current Energy","") | V20: =IF($Q20<>""," • "&$Q20,"")&IF($R20<>""," • "&$R20,"")&IF($S20<>""," • "&$S20,"")&IF($T20<>""," • "&$T20,"")&IF($U20<>""," • "&$U20,"")&" • No Blockers"
M21: =IF($D21="","",IFERROR(VLOOKUP($H21,Lists!$N$2:$O$6,2,FALSE),0)) | N21: =IF($D21="","",IF(OR($E21="Blocked",$E21="Done",$E21="Archive"),-9999,IF(AND($E21="Waiting",SUMPRODUCT((($E$5:$E$500="Next")+($E$5:$E$500="In Progress")+($E$5:$E$500="Captured"))*($D$5:$D$500<>""))>0),-500,VLOOKUP($F21,Lists!$L$2:$M$4,2,FALSE)+IF($E21="In Progress",10,0)+IF(AND($I21<>"",$I21<TODAY()),25,0)+IF(AND($I21<>"",$I21>=TODAY(),$I21<=TODAY()+7),15,0)+IF($H21="",0,IF($M21<=VLOOKUP(Home!$C$7,Lists!$N$2:$O$6,2,FALSE),20,-10))+IF($G21=Home!$E$7,15,IF(Home!$E$7="",0,-5))-ROW()/100000))) | O21: =IF($D21="","",IF($N21<=-500,"Not recommended right now",IF($E21="Waiting","Nothing else actionable right now — Waiting on: "&IF($K21="","this item",$K21),MID($V21,4,9999)))) | P21: =IF($D21="","",IF('Task Finder'!$C$6="High Priority",AND($F21="High",$E21<>"Done",$E21<>"Archive"),IF('Task Finder'!$C$6="Due This Week",AND($I21<>"",$I21>=TODAY(),$I21<=TODAY()+7,$E21<>"Done"),IF('Task Finder'!$C$6="Quick Wins (15 mins or less)",AND($M21<=15,$E21<>"Done",$E21<>"Blocked"),IF('Task Finder'!$C$6="Deep Thinking",AND($G21="Deep Thinking",$E21<>"Done"),IF('Task Finder'!$C$6="Processing",AND($G21="Processing",$E21<>"Done"),IF('Task Finder'!$C$6="Blocked",$E21="Blocked",IF('Task Finder'!$C$6="Waiting",$E21="Waiting",IF('Task Finder'!$C$6="Recently Updated",AND($L21<>"",$L21>=TODAY()-7),IF('Task Finder'!$C$6="Keyword",AND('Task Finder'!$C$7<>"",OR(ISNUMBER(SEARCH('Task Finder'!$C$7,$A21)),ISNUMBER(SEARCH('Task Finder'!$C$7,$B21)),ISNUMBER(SEARCH('Task Finder'!$C$7,$C21)),ISNUMBER(SEARCH('Task Finder'!$C$7,$D21)),ISNUMBER(SEARCH('Task Finder'!$C$7,$K21)))),TRUE)))))))))) | Q21: =IF($F21="High","High Priority","") | R21: =IF(AND($I21<>"",$I21<TODAY()),"Overdue","") | S21: =IF(AND($I21<>"",$I21>=TODAY(),$I21<=TODAY()+7),"Due This Week","") | T21: =IF(AND($H21<>"",$M21<=VLOOKUP(Home!$C$7,Lists!$N$2:$O$6,2,FALSE)),$H21&" Task","") | U21: =IF($G21=Home!$E$7,"Fits Current Energy","") | V21: =IF($Q21<>""," • "&$Q21,"")&IF($R21<>""," • "&$R21,"")&IF($S21<>""," • "&$S21,"")&IF($T21<>""," • "&$T21,"")&IF($U21<>""," • "&$U21,"")&" • No Blockers"
M22: =IF($D22="","",IFERROR(VLOOKUP($H22,Lists!$N$2:$O$6,2,FALSE),0)) | N22: =IF($D22="","",IF(OR($E22="Blocked",$E22="Done",$E22="Archive"),-9999,IF(AND($E22="Waiting",SUMPRODUCT((($E$5:$E$500="Next")+($E$5:$E$500="In Progress")+($E$5:$E$500="Captured"))*($D$5:$D$500<>""))>0),-500,VLOOKUP($F22,Lists!$L$2:$M$4,2,FALSE)+IF($E22="In Progress",10,0)+IF(AND($I22<>"",$I22<TODAY()),25,0)+IF(AND($I22<>"",$I22>=TODAY(),$I22<=TODAY()+7),15,0)+IF($H22="",0,IF($M22<=VLOOKUP(Home!$C$7,Lists!$N$2:$O$6,2,FALSE),20,-10))+IF($G22=Home!$E$7,15,IF(Home!$E$7="",0,-5))-ROW()/100000))) | O22: =IF($D22="","",IF($N22<=-500,"Not recommended right now",IF($E22="Waiting","Nothing else actionable right now — Waiting on: "&IF($K22="","this item",$K22),MID($V22,4,9999)))) | P22: =IF($D22="","",IF('Task Finder'!$C$6="High Priority",AND($F22="High",$E22<>"Done",$E22<>"Archive"),IF('Task Finder'!$C$6="Due This Week",AND($I22<>"",$I22>=TODAY(),$I22<=TODAY()+7,$E22<>"Done"),IF('Task Finder'!$C$6="Quick Wins (15 mins or less)",AND($M22<=15,$E22<>"Done",$E22<>"Blocked"),IF('Task Finder'!$C$6="Deep Thinking",AND($G22="Deep Thinking",$E22<>"Done"),IF('Task Finder'!$C$6="Processing",AND($G22="Processing",$E22<>"Done"),IF('Task Finder'!$C$6="Blocked",$E22="Blocked",IF('Task Finder'!$C$6="Waiting",$E22="Waiting",IF('Task Finder'!$C$6="Recently Updated",AND($L22<>"",$L22>=TODAY()-7),IF('Task Finder'!$C$6="Keyword",AND('Task Finder'!$C$7<>"",OR(ISNUMBER(SEARCH('Task Finder'!$C$7,$A22)),ISNUMBER(SEARCH('Task Finder'!$C$7,$B22)),ISNUMBER(SEARCH('Task Finder'!$C$7,$C22)),ISNUMBER(SEARCH('Task Finder'!$C$7,$D22)),ISNUMBER(SEARCH('Task Finder'!$C$7,$K22)))),TRUE)))))))))) | Q22: =IF($F22="High","High Priority","") | R22: =IF(AND($I22<>"",$I22<TODAY()),"Overdue","") | S22: =IF(AND($I22<>"",$I22>=TODAY(),$I22<=TODAY()+7),"Due This Week","") | T22: =IF(AND($H22<>"",$M22<=VLOOKUP(Home!$C$7,Lists!$N$2:$O$6,2,FALSE)),$H22&" Task","") | U22: =IF($G22=Home!$E$7,"Fits Current Energy","") | V22: =IF($Q22<>""," • "&$Q22,"")&IF($R22<>""," • "&$R22,"")&IF($S22<>""," • "&$S22,"")&IF($T22<>""," • "&$T22,"")&IF($U22<>""," • "&$U22,"")&" • No Blockers"
M23: =IF($D23="","",IFERROR(VLOOKUP($H23,Lists!$N$2:$O$6,2,FALSE),0)) | N23: =IF($D23="","",IF(OR($E23="Blocked",$E23="Done",$E23="Archive"),-9999,IF(AND($E23="Waiting",SUMPRODUCT((($E$5:$E$500="Next")+($E$5:$E$500="In Progress")+($E$5:$E$500="Captured"))*($D$5:$D$500<>""))>0),-500,VLOOKUP($F23,Lists!$L$2:$M$4,2,FALSE)+IF($E23="In Progress",10,0)+IF(AND($I23<>"",$I23<TODAY()),25,0)+IF(AND($I23<>"",$I23>=TODAY(),$I23<=TODAY()+7),15,0)+IF($H23="",0,IF($M23<=VLOOKUP(Home!$C$7,Lists!$N$2:$O$6,2,FALSE),20,-10))+IF($G23=Home!$E$7,15,IF(Home!$E$7="",0,-5))-ROW()/100000))) | O23: =IF($D23="","",IF($N23<=-500,"Not recommended right now",IF($E23="Waiting","Nothing else actionable right now — Waiting on: "&IF($K23="","this item",$K23),MID($V23,4,9999)))) | P23: =IF($D23="","",IF('Task Finder'!$C$6="High Priority",AND($F23="High",$E23<>"Done",$E23<>"Archive"),IF('Task Finder'!$C$6="Due This Week",AND($I23<>"",$I23>=TODAY(),$I23<=TODAY()+7,$E23<>"Done"),IF('Task Finder'!$C$6="Quick Wins (15 mins or less)",AND($M23<=15,$E23<>"Done",$E23<>"Blocked"),IF('Task Finder'!$C$6="Deep Thinking",AND($G23="Deep Thinking",$E23<>"Done"),IF('Task Finder'!$C$6="Processing",AND($G23="Processing",$E23<>"Done"),IF('Task Finder'!$C$6="Blocked",$E23="Blocked",IF('Task Finder'!$C$6="Waiting",$E23="Waiting",IF('Task Finder'!$C$6="Recently Updated",AND($L23<>"",$L23>=TODAY()-7),IF('Task Finder'!$C$6="Keyword",AND('Task Finder'!$C$7<>"",OR(ISNUMBER(SEARCH('Task Finder'!$C$7,$A23)),ISNUMBER(SEARCH('Task Finder'!$C$7,$B23)),ISNUMBER(SEARCH('Task Finder'!$C$7,$C23)),ISNUMBER(SEARCH('Task Finder'!$C$7,$D23)),ISNUMBER(SEARCH('Task Finder'!$C$7,$K23)))),TRUE)))))))))) | Q23: =IF($F23="High","High Priority","") | R23: =IF(AND($I23<>"",$I23<TODAY()),"Overdue","") | S23: =IF(AND($I23<>"",$I23>=TODAY(),$I23<=TODAY()+7),"Due This Week","") | T23: =IF(AND($H23<>"",$M23<=VLOOKUP(Home!$C$7,Lists!$N$2:$O$6,2,FALSE)),$H23&" Task","") | U23: =IF($G23=Home!$E$7,"Fits Current Energy","") | V23: =IF($Q23<>""," • "&$Q23,"")&IF($R23<>""," • "&$R23,"")&IF($S23<>""," • "&$S23,"")&IF($T23<>""," • "&$T23,"")&IF($U23<>""," • "&$U23,"")&" • No Blockers"
M24: =IF($D24="","",IFERROR(VLOOKUP($H24,Lists!$N$2:$O$6,2,FALSE),0)) | N24: =IF($D24="","",IF(OR($E24="Blocked",$E24="Done",$E24="Archive"),-9999,IF(AND($E24="Waiting",SUMPRODUCT((($E$5:$E$500="Next")+($E$5:$E$500="In Progress")+($E$5:$E$500="Captured"))*($D$5:$D$500<>""))>0),-500,VLOOKUP($F24,Lists!$L$2:$M$4,2,FALSE)+IF($E24="In Progress",10,0)+IF(AND($I24<>"",$I24<TODAY()),25,0)+IF(AND($I24<>"",$I24>=TODAY(),$I24<=TODAY()+7),15,0)+IF($H24="",0,IF($M24<=VLOOKUP(Home!$C$7,Lists!$N$2:$O$6,2,FALSE),20,-10))+IF($G24=Home!$E$7,15,IF(Home!$E$7="",0,-5))-ROW()/100000))) | O24: =IF($D24="","",IF($N24<=-500,"Not recommended right now",IF($E24="Waiting","Nothing else actionable right now — Waiting on: "&IF($K24="","this item",$K24),MID($V24,4,9999)))) | P24: =IF($D24="","",IF('Task Finder'!$C$6="High Priority",AND($F24="High",$E24<>"Done",$E24<>"Archive"),IF('Task Finder'!$C$6="Due This Week",AND($I24<>"",$I24>=TODAY(),$I24<=TODAY()+7,$E24<>"Done"),IF('Task Finder'!$C$6="Quick Wins (15 mins or less)",AND($M24<=15,$E24<>"Done",$E24<>"Blocked"),IF('Task Finder'!$C$6="Deep Thinking",AND($G24="Deep Thinking",$E24<>"Done"),IF('Task Finder'!$C$6="Processing",AND($G24="Processing",$E24<>"Done"),IF('Task Finder'!$C$6="Blocked",$E24="Blocked",IF('Task Finder'!$C$6="Waiting",$E24="Waiting",IF('Task Finder'!$C$6="Recently Updated",AND($L24<>"",$L24>=TODAY()-7),IF('Task Finder'!$C$6="Keyword",AND('Task Finder'!$C$7<>"",OR(ISNUMBER(SEARCH('Task Finder'!$C$7,$A24)),ISNUMBER(SEARCH('Task Finder'!$C$7,$B24)),ISNUMBER(SEARCH('Task Finder'!$C$7,$C24)),ISNUMBER(SEARCH('Task Finder'!$C$7,$D24)),ISNUMBER(SEARCH('Task Finder'!$C$7,$K24)))),TRUE)))))))))) | Q24: =IF($F24="High","High Priority","") | R24: =IF(AND($I24<>"",$I24<TODAY()),"Overdue","") | S24: =IF(AND($I24<>"",$I24>=TODAY(),$I24<=TODAY()+7),"Due This Week","") | T24: =IF(AND($H24<>"",$M24<=VLOOKUP(Home!$C$7,Lists!$N$2:$O$6,2,FALSE)),$H24&" Task","") | U24: =IF($G24=Home!$E$7,"Fits Current Energy","") | V24: =IF($Q24<>""," • "&$Q24,"")&IF($R24<>""," • "&$R24,"")&IF($S24<>""," • "&$S24,"")&IF($T24<>""," • "&$T24,"")&IF($U24<>""," • "&$U24,"")&" • No Blockers"
